Workbook

Sheet Read Me
A1: Qualtrics Employee Experience Scoping Questionnaire
A2: SAP SuccessFactors (Employee Central and PMGM live) + Qualtrics EX | Go-live target in 3-4 months | Prepared 28 Oct 2026
A4: Client | B4: [Client name]
A5: Prepared by | B5: [Consultant / firm]
A6: Purpose | B6: Gather the information needed to scope, size and sequence a Qualtrics Employee Experience (EX) implementation alongside SAP SuccessFactors, so the project can reach go-live in 3-4 months.
A7: Context we assume | B7: Employee Central and Performance & Goals (PMGM) are live. Other SuccessFactors modules are upcoming and some may go live in the same window. Treat every assumption here as a question to confirm.
A8: How to use | B8: 1) Start with the Use Case Map and mark each use case Wave 1 / Phase 2 / Out. 2) Answer the Questionnaire tab, starting with rows marked with a star (kick-off questions). 3) Complete the SF Module Readiness and Data Inventory tabs. 4) Review the 16-week plan and risks. Work in the yellow cells.
A9: Priority | B9: P1 = must answer to avoid blocking design or build. P2 = should answer before build. P3 = nice to have or Phase 2.
A10: Needed by | B10: Week 2 = needed in discovery. Week 4 = needed to finish design. Week 8 = needed before build completes. Post go-live = can follow launch.
A11: Status values | B11: Not started, In progress, Answered, Follow-up needed, Not applicable. The Summary tab counts these automatically.
A12: Colour key | B12: Yellow fill = cell for the client to complete. Blue text = date or number input you may change. Black text = formula or fixed content.
A13: Product caution | B13: SAP and Qualtrics product names, packaging and integration options change often. Where a question mentions a product option, treat it as something to validate with SAP and Qualtrics, not as a commitment.
A14: Sources | B14: See the Sources tab. Qualtrics 360 terms (subject, evaluator, directory, administrator types, workflows, waves) come from the Qualtrics Support page you provided.
A16: Example of a completed row
A17: ID | B17: LCE-05
A18: Question | B18: How should exit surveys work: which exit types are included, and should they be sent before or after the last day?
A19: Client response (example) | B19: Resignation and retirement only; dismissal and contract end excluded. Send 3 days after last working day to personal email; HR owns the exit programme.
A20: Status (example) | B20: Answered
A21: Respondent (example) | B21: Priya Menon, Head of HR Operations
A22: Follow-up (example) | B22: Confirm personal-email consent wording with Legal by end of Week 3.

Sheet Summary
A1: Progress Summary
A2: All figures calculate from the Questionnaire tab.
A4: Section | B4: Questions | C4: P1 questions | D4: Answered / N/A | E4: Open | F4: % complete | G4: P1 still open
A5: Project Context & Objectives | B5: =COUNTIFS(Questionnaire!$B$5:$B$204,$A5) -> 11 | C5: =COUNTIFS(Questionnaire!$B$5:$B$204,$A5,Questionnaire!$G$5:$G$204,"P1*") -> 8 | D5: =COUNTIFS(Questionnaire!$B$5:$B$204,$A5,Questionnaire!$L$5:$L$204,"Answered")+COUNTIFS(Questionnaire!$B$5:$B$204,$A5,Questionnaire!$L$5:$L$204,"Not applicable") -> 0 | E5: =B5-D5 -> 11 | F5: =IF(B5=0,0,D5/B5) -> 0 | G5: =C5-COUNTIFS(Questionnaire!$B$5:$B$204,$A5,Questionnaire!$G$5:$G$204,"P1*",Questionnaire!$L$5:$L$204,"Answered")-COUNTIFS(Questionnaire!$B$5:$B$204,$A5,Questionnaire!$G$5:$G$204,"P1*",Questionnaire!$L$5:$L$204,"Not applicable") -> 8
A6: Use-Case Selection & Prioritisation | B6: =COUNTIFS(Questionnaire!$B$5:$B$204,$A6) -> 9 | C6: =COUNTIFS(Questionnaire!$B$5:$B$204,$A6,Questionnaire!$G$5:$G$204,"P1*") -> 6 | D6: =COUNTIFS(Questionnaire!$B$5:$B$204,$A6,Questionnaire!$L$5:$L$204,"Answered")+COUNTIFS(Questionnaire!$B$5:$B$204,$A6,Questionnaire!$L$5:$L$204,"Not applicable") -> 0 | E6: =B6-D6 -> 9 | F6: =IF(B6=0,0,D6/B6) -> 0 | G6: =C6-COUNTIFS(Questionnaire!$B$5:$B$204,$A6,Questionnaire!$G$5:$G$204,"P1*",Questionnaire!$L$5:$L$204,"Answered")-COUNTIFS(Questionnaire!$B$5:$B$204,$A6,Questionnaire!$G$5:$G$204,"P1*",Questionnaire!$L$5:$L$204,"Not applicable") -> 6
A7: Licensing, Commercials & Contracting | B7: =COUNTIFS(Questionnaire!$B$5:$B$204,$A7) -> 8 | C7: =COUNTIFS(Questionnaire!$B$5:$B$204,$A7,Questionnaire!$G$5:$G$204,"P1*") -> 5 | D7: =COUNTIFS(Questionnaire!$B$5:$B$204,$A7,Questionnaire!$L$5:$L$204,"Answered")+COUNTIFS(Questionnaire!$B$5:$B$204,$A7,Questionnaire!$L$5:$L$204,"Not applicable") -> 0 | E7: =B7-D7 -> 8 | F7: =IF(B7=0,0,D7/B7) -> 0 | G7: =C7-COUNTIFS(Questionnaire!$B$5:$B$204,$A7,Questionnaire!$G$5:$G$204,"P1*",Questionnaire!$L$5:$L$204,"Answered")-COUNTIFS(Questionnaire!$B$5:$B$204,$A7,Questionnaire!$G$5:$G$204,"P1*",Questionnaire!$L$5:$L$204,"Not applicable") -> 5
A8: Employee Engagement Survey | B8: =COUNTIFS(Questionnaire!$B$5:$B$204,$A8) -> 11 | C8: =COUNTIFS(Questionnaire!$B$5:$B$204,$A8,Questionnaire!$G$5:$G$204,"P1*") -> 7 | D8: =COUNTIFS(Questionnaire!$B$5:$B$204,$A8,Questionnaire!$L$5:$L$204,"Answered")+COUNTIFS(Questionnaire!$B$5:$B$204,$A8,Questionnaire!$L$5:$L$204,"Not applicable") -> 0 | E8: =B8-D8 -> 11 | F8: =IF(B8=0,0,D8/B8) -> 0 | G8: =C8-COUNTIFS(Questionnaire!$B$5:$B$204,$A8,Questionnaire!$G$5:$G$204,"P1*",Questionnaire!$L$5:$L$204,"Answered")-COUNTIFS(Questionnaire!$B$5:$B$204,$A8,Questionnaire!$G$5:$G$204,"P1*",Questionnaire!$L$5:$L$204,"Not applicable") -> 7
A9: Pulse & Ad Hoc Listening | B9: =COUNTIFS(Questionnaire!$B$5:$B$204,$A9) -> 8 | C9: =COUNTIFS(Questionnaire!$B$5:$B$204,$A9,Questionnaire!$G$5:$G$204,"P1*") -> 3 | D9: =COUNTIFS(Questionnaire!$B$5:$B$204,$A9,Questionnaire!$L$5:$L$204,"Answered")+COUNTIFS(Questionnaire!$B$5:$B$204,$A9,Questionnaire!$L$5:$L$204,"Not applicable") -> 0 | E9: =B9-D9 -> 8 | F9: =IF(B9=0,0,D9/B9) -> 0 | G9: =C9-COUNTIFS(Questionnaire!$B$5:$B$204,$A9,Questionnaire!$G$5:$G$204,"P1*",Questionnaire!$L$5:$L$204,"Answered")-COUNTIFS(Questionnaire!$B$5:$B$204,$A9,Questionnaire!$G$5:$G$204,"P1*",Questionnaire!$L$5:$L$204,"Not applicable") -> 3
A10: Lifecycle Moments: Onboarding, Exit & Candidate | B10: =COUNTIFS(Questionnaire!$B$5:$B$204,$A10) -> 14 | C10: =COUNTIFS(Questionnaire!$B$5:$B$204,$A10,Questionnaire!$G$5:$G$204,"P1*") -> 8 | D10: =COUNTIFS(Questionnaire!$B$5:$B$204,$A10,Questionnaire!$L$5:$L$204,"Answered")+COUNTIFS(Questionnaire!$B$5:$B$204,$A10,Questionnaire!$L$5:$L$204,"Not applicable") -> 0 | E10: =B10-D10 -> 14 | F10: =IF(B10=0,0,D10/B10) -> 0 | G10: =C10-COUNTIFS(Questionnaire!$B$5:$B$204,$A10,Questionnaire!$G$5:$G$204,"P1*",Questionnaire!$L$5:$L$204,"Answered")-COUNTIFS(Questionnaire!$B$5:$B$204,$A10,Questionnaire!$G$5:$G$204,"P1*",Questionnaire!$L$5:$L$204,"Not applicable") -> 8
A11: 360 / Multi-Rater Feedback | B11: =COUNTIFS(Questionnaire!$B$5:$B$204,$A11) -> 14 | C11: =COUNTIFS(Questionnaire!$B$5:$B$204,$A11,Questionnaire!$G$5:$G$204,"P1*") -> 8 | D11: =COUNTIFS(Questionnaire!$B$5:$B$204,$A11,Questionnaire!$L$5:$L$204,"Answered")+COUNTIFS(Questionnaire!$B$5:$B$204,$A11,Questionnaire!$L$5:$L$204,"Not applicable") -> 0 | E11: =B11-D11 -> 14 | F11: =IF(B11=0,0,D11/B11) -> 0 | G11: =C11-COUNTIFS(Questionnaire!$B$5:$B$204,$A11,Questionnaire!$G$5:$G$204,"P1*",Questionnaire!$L$5:$L$204,"Answered")-COUNTIFS(Questionnaire!$B$5:$B$204,$A11,Questionnaire!$G$5:$G$204,"P1*",Questionnaire!$L$5:$L$204,"Not applicable") -> 8
A12: Manager Effectiveness & Action Planning | B12: =COUNTIFS(Questionnaire!$B$5:$B$204,$A12) -> 9 | C12: =COUNTIFS(Questionnaire!$B$5:$B$204,$A12,Questionnaire!$G$5:$G$204,"P1*") -> 3 | D12: =COUNTIFS(Questionnaire!$B$5:$B$204,$A12,Questionnaire!$L$5:$L$204,"Answered")+COUNTIFS(Questionnaire!$B$5:$B$204,$A12,Questionnaire!$L$5:$L$204,"Not applicable") -> 0 | E12: =B12-D12 -> 9 | F12: =IF(B12=0,0,D12/B12) -> 0 | G12: =C12-COUNTIFS(Questionnaire!$B$5:$B$204,$A12,Questionnaire!$G$5:$G$204,"P1*",Questionnaire!$L$5:$L$204,"Answered")-COUNTIFS(Questionnaire!$B$5:$B$204,$A12,Questionnaire!$G$5:$G$204,"P1*",Questionnaire!$L$5:$L$204,"Not applicable") -> 3
A13: Employee Technology Experience | B13: =COUNTIFS(Questionnaire!$B$5:$B$204,$A13) -> 7 | C13: =COUNTIFS(Questionnaire!$B$5:$B$204,$A13,Questionnaire!$G$5:$G$204,"P1*") -> 1 | D13: =COUNTIFS(Questionnaire!$B$5:$B$204,$A13,Questionnaire!$L$5:$L$204,"Answered")+COUNTIFS(Questionnaire!$B$5:$B$204,$A13,Questionnaire!$L$5:$L$204,"Not applicable") -> 0 | E13: =B13-D13 -> 7 | F13: =IF(B13=0,0,D13/B13) -> 0 | G13: =C13-COUNTIFS(Questionnaire!$B$5:$B$204,$A13,Questionnaire!$G$5:$G$204,"P1*",Questionnaire!$L$5:$L$204,"Answered")-COUNTIFS(Questionnaire!$B$5:$B$204,$A13,Questionnaire!$G$5:$G$204,"P1*",Questionnaire!$L$5:$L$204,"Not applicable") -> 1
A14: Survey Content, Scales & Languages | B14: =COUNTIFS(Questionnaire!$B$5:$B$204,$A14) -> 10 | C14: =COUNTIFS(Questionnaire!$B$5:$B$204,$A14,Questionnaire!$G$5:$G$204,"P1*") -> 5 | D14: =COUNTIFS(Questionnaire!$B$5:$B$204,$A14,Questionnaire!$L$5:$L$204,"Answered")+COUNTIFS(Questionnaire!$B$5:$B$204,$A14,Questionnaire!$L$5:$L$204,"Not applicable") -> 0 | E14: =B14-D14 -> 10 | F14: =IF(B14=0,0,D14/B14) -> 0 | G14: =C14-COUNTIFS(Questionnaire!$B$5:$B$204,$A14,Questionnaire!$G$5:$G$204,"P1*",Questionnaire!$L$5:$L$204,"Answered")-COUNTIFS(Questionnaire!$B$5:$B$204,$A14,Questionnaire!$G$5:$G$204,"P1*",Questionnaire!$L$5:$L$204,"Not applicable") -> 5
A15: SuccessFactors Integration & Architecture | B15: =COUNTIFS(Questionnaire!$B$5:$B$204,$A15) -> 15 | C15: =COUNTIFS(Questionnaire!$B$5:$B$204,$A15,Questionnaire!$G$5:$G$204,"P1*") -> 10 | D15: =COUNTIFS(Questionnaire!$B$5:$B$204,$A15,Questionnaire!$L$5:$L$204,"Answered")+COUNTIFS(Questionnaire!$B$5:$B$204,$A15,Questionnaire!$L$5:$L$204,"Not applicable") -> 0 | E15: =B15-D15 -> 15 | F15: =IF(B15=0,0,D15/B15) -> 0 | G15: =C15-COUNTIFS(Questionnaire!$B$5:$B$204,$A15,Questionnaire!$G$5:$G$204,"P1*",Questionnaire!$L$5:$L$204,"Answered")-COUNTIFS(Questionnaire!$B$5:$B$204,$A15,Questionnaire!$G$5:$G$204,"P1*",Questionnaire!$L$5:$L$204,"Not applicable") -> 10
A16: Employee Data, Hierarchy & Attributes | B16: =COUNTIFS(Questionnaire!$B$5:$B$204,$A16) -> 13 | C16: =COUNTIFS(Questionnaire!$B$5:$B$204,$A16,Questionnaire!$G$5:$G$204,"P1*") -> 10 | D16: =COUNTIFS(Questionnaire!$B$5:$B$204,$A16,Questionnaire!$L$5:$L$204,"Answered")+COUNTIFS(Questionnaire!$B$5:$B$204,$A16,Questionnaire!$L$5:$L$204,"Not applicable") -> 0 | E16: =B16-D16 -> 13 | F16: =IF(B16=0,0,D16/B16) -> 0 | G16: =C16-COUNTIFS(Questionnaire!$B$5:$B$204,$A16,Questionnaire!$G$5:$G$204,"P1*",Questionnaire!$L$5:$L$204,"Answered")-COUNTIFS(Questionnaire!$B$5:$B$204,$A16,Questionnaire!$G$5:$G$204,"P1*",Questionnaire!$L$5:$L$204,"Not applicable") -> 10
... A23: Success Measures & Operating Model | B23: =COUNTIFS(Questionnaire!$B$5:$B$204,$A23) -> 8 | C23: =COUNTIFS(Questionnaire!$B$5:$B$204,$A23,Questionnaire!$G$5:$G$204,"P1*") -> 2 | D23: =COUNTIFS(Questionnaire!$B$5:$B$204,$A23,Questionnaire!$L$5:$L$204,"Answered")+COUNTIFS(Questionnaire!$B$5:$B$204,$A23,Questionnaire!$L$5:$L$204,"Not applicable") -> 0 | E23: =B23-D23 -> 8 | F23: =IF(B23=0,0,D23/B23) -> 0 | G23: =C23-COUNTIFS(Questionnaire!$B$5:$B$204,$A23,Questionnaire!$G$5:$G$204,"P1*",Questionnaire!$L$5:$L$204,"Answered")-COUNTIFS(Questionnaire!$B$5:$B$204,$A23,Questionnaire!$G$5:$G$204,"P1*",Questionnaire!$L$5:$L$204,"Not applicable") -> 2
A24: Total | B24: =SUM(B5:B23) -> 200 | C24: =SUM(C5:C23) -> 113 | D24: =SUM(D5:D23) -> 0 | E24: =SUM(E5:E23) -> 200 | F24: =IF(B24=0,0,D24/B24) -> 0 | G24: =SUM(G5:G23) -> 113
A26: By priority
A27: Priority | B27: Questions | C27: Answered / N/A | D27: Open
A28: P1 - Must answer | B28: =COUNTIFS(Questionnaire!$G$5:$G$204,$A28) -> 113 | C28: =COUNTIFS(Questionnaire!$G$5:$G$204,$A28,Questionnaire!$L$5:$L$204,"Answered")+COUNTIFS(Questionnaire!$G$5:$G$204,$A28,Questionnaire!$L$5:$L$204,"Not applicable") -> 0 | D28: =B28-C28 -> 113
A29: P2 - Should answer | B29: =COUNTIFS(Questionnaire!$G$5:$G$204,$A29) -> 78 | C29: =COUNTIFS(Questionnaire!$G$5:$G$204,$A29,Questionnaire!$L$5:$L$204,"Answered")+COUNTIFS(Questionnaire!$G$5:$G$204,$A29,Questionnaire!$L$5:$L$204,"Not applicable") -> 0 | D29: =B29-C29 -> 78
A30: P3 - Nice to have | B30: =COUNTIFS(Questionnaire!$G$5:$G$204,$A30) -> 9 | C30: =COUNTIFS(Questionnaire!$G$5:$G$204,$A30,Questionnaire!$L$5:$L$204,"Answered")+COUNTIFS(Questionnaire!$G$5:$G$204,$A30,Questionnaire!$L$5:$L$204,"Not applicable") -> 0 | D30: =B30-C30 -> 9
A32: By needed-by milestone
A33: Needed by | B33: Questions | C33: Answered / N/A | D33: Open
A34: Week 2 | B34: =COUNTIFS(Questionnaire!$J$5:$J$204,$A34) -> 50 | C34: =COUNTIFS(Questionnaire!$J$5:$J$204,$A34,Questionnaire!$L$5:$L$204,"Answered")+COUNTIFS(Questionnaire!$J$5:$J$204,$A34,Questionnaire!$L$5:$L$204,"Not applicable") -> 0 | D34: =B34-C34 -> 50
A35: Week 4 | B35: =COUNTIFS(Questionnaire!$J$5:$J$204,$A35) -> 82 | C35: =COUNTIFS(Questionnaire!$J$5:$J$204,$A35,Questionnaire!$L$5:$L$204,"Answered")+COUNTIFS(Questionnaire!$J$5:$J$204,$A35,Questionnaire!$L$5:$L$204,"Not applicable") -> 0 | D35: =B35-C35 -> 82
A36: Week 8 | B36: =COUNTIFS(Questionnaire!$J$5:$J$204,$A36) -> 53 | C36: =COUNTIFS(Questionnaire!$J$5:$J$204,$A36,Questionnaire!$L$5:$L$204,"Answered")+COUNTIFS(Questionnaire!$J$5:$J$204,$A36,Questionnaire!$L$5:$L$204,"Not applicable") -> 0 | D36: =B36-C36 -> 53
A37: Post go-live | B37: =COUNTIFS(Questionnaire!$J$5:$J$204,$A37) -> 15 | C37: =COUNTIFS(Questionnaire!$J$5:$J$204,$A37,Questionnaire!$L$5:$L$204,"Answered")+COUNTIFS(Questionnaire!$J$5:$J$204,$A37,Questionnaire!$L$5:$L$204,"Not applicable") -> 0 | D37: =B37-C37 -> 15

Sheet Use Case Map
A1: Use Case Map
A2: Mark each use case for scope. The 'Fit for 3-4 month window' column is our starting hypothesis, to be challenged in discovery.
A4: Use case | B4: What it covers | C4: Typical SuccessFactors trigger / data | D4: Depends on | E4: Fit for 3-4 month window | F4: Why (hypothesis) | G4: Scope decision | H4: Business owner | I4: Audience / population | J4: Annual volume | K4: Comments
A5: Annual Engagement | B5: Census survey of engagement, drivers and manager effectiveness with hierarchy-based reporting. | C5: EC person, job and organisation data; reporting lines | D5: EC only (live) | E5: High | F5: Needs EC data only; the biggest effort is content, anonymity design and reporting roles.
A6: Pulse & Ad Hoc | B6: Short recurring or event-driven surveys, including a SuccessFactors adoption pulse. | C6: EC participant file; optional SF home-page embed | D6: EC only (live) | E6: High | F6: Reuses the engagement foundation; quickest visible value.
A7: Onboarding | B7: Surveys at set days after hire for new hire, manager and buddy. | C7: EC hire date, position start, manager, event reason | D7: EC hire events; richer if SF Onboarding is live | E7: Medium-High | F7: Trigger works from EC; check hiring volumes, event reasons and email availability before day one.
A8: Exit | B8: Leaver feedback and attrition drivers, before or after the last day. | C8: EC termination event, termination date, reason, contact data | D8: EC termination events; offboarding process | E8: Medium-High | F8: Needs reliable termination data and a personal-contact policy; legal sensitivity is high.
A9: Candidate Experience | B9: Feedback from applicants across hiring stages. | C9: Recruiting stages, requisition and applicant data | D9: SF Recruiting (planned) | E9: Low-Medium | F9: Depends on Recruiting being live and on applicant-privacy rules; usually a Phase 2 candidate.
A10: 360 / Multi-Rater | B10: Subjects receive feedback from self and evaluators; workflows can be predefined, nominated or open. | C10: EC reporting lines, subject and evaluator lists, competency model | D10: EC; PMGM overlap decision | E10: Medium | F10: Needs competency content, rater workflow and a decision against PMGM multi-rater; plan waves.
A11: Manager Effectiveness & Action Planning | B11: Manager dashboards, upward feedback and tracked action plans. | C11: EC manager hierarchy; engagement results | D11: Engagement or pulse results | E11: Medium-High | F11: Builds on engagement; the key risks are small-team anonymity and manager capability.
A12: Employee Technology Experience | B12: Feedback on tools and services, including SuccessFactors itself. | C12: EC participants; optional ITSM events | D12: Optional ITSM integration | E12: Medium | F12: SF-adoption pulse is a quick win; ITSM integration is Phase 2.
A13: Internal Moves & Return from Leave | B13: Surveys after promotion, transfer, leave return or manager change. | C13: EC event reasons, status changes | D13: EC events; data quality | E13: Low-Medium | F13: Same mechanics as onboarding; usually follows once triggers are proven.
A14: Well-Being & Inclusion | B14: Targeted surveys on well-being, belonging and inclusion. | C14: EC demographics where permitted | D14: Legal approval for sensitive data | E14: Medium | F14: Content and legal review dominate; the platform work is light.
A15: Change & Project Pulses | B15: Rapid feedback on restructuring, policy change or return-to-office. | C15: EC participant selection | D15: EC only (live) | E15: High | F15: Easy once the foundation exists; needs governance to avoid fatigue.

Sheet Questionnaire
A1: Scoping Questionnaire
A2: 200 questions across 19 sections. Filter by section, use case, priority, owner or needed-by. Complete the yellow columns.
A4: ID | B4: Section | C4: Use case(s) | D4: Question | E4: Why we ask / guidance | F4: Response type | G4: Priority | H4: Kick-off | I4: Primary owner | J4: Needed by | K4: Client response | L4: Status | M4: Respondent | N4: Follow-up / notes
A5: CTX-01 | B5: Project Context & Objectives | C5: ALL | D5: What are the top three business outcomes you expect from Qualtrics EX (for example lower regretted attrition, higher engagement, better onboarding, stronger managers, SuccessFactors adoption)? Please rank them. | E5: Outcomes decide which use cases go first and how success is judged. | F5: List / table | G5: P1 - Must answer | H5: ★ | I5: Executive Sponsor | J5: Week 2 | L5: Not started
A6: CTX-02 | B6: Project Context & Objectives | C6: ALL | D6: Who is the executive sponsor, and what decision rights do they hold over scope, budget and the go-live date? | E6: Avoids stalled decisions in a 3-4 month window. | F6: Free text | G6: P1 - Must answer | H6: ★ | I6: Executive Sponsor | J6: Week 2 | L6: Not started
A7: CTX-03 | B7: Project Context & Objectives | C7: ALL | D7: Which employee listening tools, vendors and programmes run today (engagement, pulse, onboarding, exit, 360)? Please share the last 24 months of results, response rates and survey instruments. | E7: Gives baselines and reusable content. Qualtrics itself advises gathering previous reports as a reference point. | F7: List / table | G7: P1 - Must answer | H7: ★ | I7: HR / People Leadership | J7: Week 2 | L7: Not started
A8: CTX-04 | B8: Project Context & Objectives | C8: ALL | D8: Which existing survey programmes must be replaced, kept, or run in parallel at go-live? | E8: Drives migration, trend continuity and communication. | F8: Single choice | G8: P1 - Must answer | I8: HR / People Leadership | J8: Week 4 | L8: Not started
A9: CTX-05 | B9: Project Context & Objectives | C9: ALL | D9: Workforce profile: headcount, countries, legal entities, worker types (employees, contingent, interns), share of shift or deskless staff, and languages spoken. | E9: Sizes licences, languages, delivery channels and test scope. | F9: List / table | G9: P1 - Must answer | H9: ★ | I9: HR / People Leadership | J9: Week 2 | L9: Not started
A10: CTX-06 | B10: Project Context & Objectives | C10: ALL | D10: Is the go-live date fixed? What drives it (contract start, board commitment, business event) and what is the cost of moving it by four weeks? | E10: Tells us whether to cut scope or move the date when trade-offs appear. | F10: Free text | G10: P1 - Must answer | H10: ★ | I10: Executive Sponsor | J10: Week 2 | L10: Not started
A11: CTX-07 | B11: Project Context & Objectives | C11: ALL | D11: Which other programmes compete for the same HR, HRIS, IT and communications people over the next four months (other SF module go-lives, payroll cycles, M&A, restructuring)? | E11: Capacity clashes are a leading cause of slippage. | F11: List / table | G11: P1 - Must answer | I11: Project / PMO | J11: Week 2 | L11: Not started
A12: CTX-08 | B12: Project Context & Objectives | C12: ALL | D12: Who will own EX after go-live (HR, People Analytics, IT, Internal Comms) and how large is the run team? | E12: The design must match the team that will operate it. | F12: Free text | G12: P2 - Should answer | I12: HR / People Leadership | J12: Week 4 | L12: Not started
A13: CTX-09 | B13: Project Context & Objectives | C13: ALL | D13: Is there an EX framework, employee value proposition or people strategy that survey content and dashboards should align to? | E13: Keeps content and reporting consistent with strategy. | F13: Free text | G13: P2 - Should answer | I13: HR / People Leadership | J13: Week 4 | L13: Not started
A14: CTX-10 | B14: Project Context & Objectives | C14: ALL | D14: What has worked or failed in past listening efforts (low participation, survey fatigue, no visible action, trust issues)? | E14: Prevents repeating known failures. | F14: Free text | G14: P2 - Should answer | I14: HR / People Leadership | J14: Week 4 | L14: Not started
A15: CTX-11 | B15: Project Context & Objectives | C15: ALL | D15: Is Qualtrics already used elsewhere in the organisation (CX, brand, research)? If so, share tenant details, data centre and existing administrators. | E15: Lets us reuse existing tenant, SSO and security approvals. | F15: List / table | G15: P1 - Must answer | H15: ★ | I15: IT / Architecture | J15: Week 2 | L15: Not started
A16: USE-01 | B16: Use-Case Selection & Prioritisation | C16: ALL | D16: For each use case on the Use Case Map tab, mark Wave 1 (go-live), Phase 2, or Out of scope. | E16: The core scoping decision; everything else follows from it. | F16: List / table | G16: P1 - Must answer | H16: ★ | I16: Executive Sponsor | J16: Week 2 | L16: Not started
A17: USE-02 | B17: Use-Case Selection & Prioritisation | C17: ALL | D17: For each in-scope use case, who is the business owner, who is the audience, and what decision will the data drive? | E17: A use case without an owner and a decision becomes shelfware. | F17: List / table | G17: P1 - Must answer | I17: HR / People Leadership | J17: Week 2 | L17: Not started
A18: USE-03 | B18: Use-Case Selection & Prioritisation | C18: ALL | D18: If only one or two use cases could be live in 3-4 months, which would they be and why? | E18: Forces a realistic minimum viable launch. | F18: Free text | G18: P1 - Must answer | H18: ★ | I18: Executive Sponsor | J18: Week 2 | L18: Not started
A19: USE-04 | B19: Use-Case Selection & Prioritisation | C19: ONB, EXT, CAN | D19: Which use cases depend on SuccessFactors modules that are not yet live, and could they start with a file-based or manual trigger? | E19: Lets lifecycle use cases launch without waiting for every module. | F19: Free text | G19: P1 - Must answer | H19: ★ | I19: HRIS / SuccessFactors Lead | J19: Week 4 | L19: Not started
A20: USE-05 | B20: Use-Case Selection & Prioritisation | C20: ALL | D20: Beyond the standard list, are there other use cases (M&A integration, return-to-office, restructuring, safety culture, well-being, inclusion, SuccessFactors adoption)? | E20: Surfaces ad hoc needs early so the design stays flexible. | F20: Multi-select | G20: P2 - Should answer | I20: HR / People Leadership | J20: Week 4 | L20: Not started
A21: USE-06 | B21: Use-Case Selection & Prioritisation | C21: ALL | D21: Which populations are in scope for each use case (all employees, countries, entities, job families, new joiners, leavers, contingent workers)? | E21: Determines the participant file, licences and legal review. | F21: List / table | G21: P1 - Must answer | I21: HR / People Leadership | J21: Week 4 | L21: Not started
A22: USE-07 | B22: Use-Case Selection & Prioritisation | C22: ALL | D22: How often must each use case run (annual, quarterly, event-triggered, always-on), and what are the blackout periods (year-end, payroll, appraisal cycles, local holidays)? | E22: Builds the listening calendar and avoids fatigue and clashes. | F22: List / table | G22: P1 - Must answer | H22: ★ | I22: HR / People Leadership | J22: Week 4 | L22: Not started
A23: USE-08 | B23: Use-Case Selection & Prioritisation | C23: ALL | D23: Will one listening calendar govern engagement, pulse and lifecycle surveys, and who owns it? | E23: Caps total surveys per employee and avoids overlap. | F23: Free text | G23: P2 - Should answer | I23: HR / People Leadership | J23: Week 8 | L23: Not started
A24: USE-09 | B24: Use-Case Selection & Prioritisation | C24: 360, ENG, PLS | D24: Which surveys should be tied to the SF PMGM cycle (for example 360 feedback inside the performance cycle, or a post-review pulse)? | E24: Aligns timing and avoids stacking requests on managers. | F24: Free text | G24: P2 - Should answer | I24: Talent & L&D | J24: Week 4 | L24: Not started
A25: COM-01 | B25: Licensing, Commercials & Contracting | C25: ALL | D25: How is Qualtrics EX contracted: SAP Endorsed Apps agreement, directly with Qualtrics, or via a reseller? Which products or SKUs (Engagement, Pulse, Onboarding, Exit, 360, Lifecycle, Employee Technology Experience)? | E25: Licensed products set what can be configured and when. SAP and Qualtrics announced an Endorsed Apps route in January 2025. | F25: Single choice | G25: P1 - Must answer | H25: ★ | I25: Finance / Procurement | J25: Week 2 | L25: Not started
A26: COM-02 | B26: Licensing, Commercials & Contracting | C26: ALL | D26: What are the licensed participant counts per product, and the contract start date and term? Does the licence start before the build begins? | E26: A late licence start blocks tenant access and build. | F26: Number | G26: P1 - Must answer | I26: Finance / Procurement | J26: Week 2 | L26: Not started
A27: COM-03 | B27: Licensing, Commercials & Contracting | C27: ALL | D27: Is the Qualtrics tenant (brand) already provisioned, and in which data centre region? | E27: Region drives data residency and is hard to change later. | F27: Yes / No | G27: P1 - Must answer | H27: ★ | I27: IT / Architecture | J27: Week 2 | L27: Not started
A28: COM-04 | B28: Licensing, Commercials & Contracting | C28: RPT | D28: Are AI features (Qualtrics Assist, text analytics, conversational feedback) licensed, and permitted under your internal AI policy? | E28: AI features may need separate approval. | F28: Yes / No | G28: P2 - Should answer | H28: ★ | I28: IT / Architecture | J28: Week 4 | L28: Not started
A29: COM-05 | B29: Licensing, Commercials & Contracting | C29: ALL | D29: What budget is approved for implementation, change management, translation and run costs (admin effort, partner support)? | E29: Sets realistic scope. | F29: Free text | G29: P2 - Should answer | I29: Finance / Procurement | J29: Week 4 | L29: Not started
A30: COM-06 | B30: Licensing, Commercials & Contracting | C30: ALL | D30: Who is the implementation partner, and which SAP and Qualtrics contacts (account executives, solution architects) are engaged? | E30: Shows who can unblock licence, tenant and integration questions. | F30: Free text | G30: P1 - Must answer | H30: ★ | I30: Project / PMO | J30: Week 2 | L30: Not started
A31: COM-07 | B31: Licensing, Commercials & Contracting | C31: ALL | D31: What is the status of procurement, vendor risk assessment and data processing agreements for Qualtrics, and how long do these normally take? | E31: Security and legal reviews can exceed eight weeks. | F31: Free text | G31: P1 - Must answer | H31: ★ | I31: Security & Privacy | J31: Week 2 | L31: Not started
A32: COM-08 | B32: Licensing, Commercials & Contracting | C32: INT | D32: Are there other costs to plan for: integration middleware (SAP BTP / Integration Suite), SSO, premium support, benchmarks? | E32: Avoids late surprises. | F32: List / table | G32: P2 - Should answer | I32: Finance / Procurement | J32: Week 4 | L32: Not started
A33: ENG-01 | B33: Employee Engagement Survey | C33: ENG | D33: Is there an existing engagement model or index (composite index, eNPS, drivers)? Must trend continuity with historical results be preserved? | E33: Changing items breaks year-on-year comparison. | F33: Free text | G33: P1 - Must answer | H33: ★ | I33: HR / People Leadership | J33: Week 4 | L33: Not started
A34: ENG-02 | B34: Employee Engagement Survey | C34: ENG | D34: Will you use the Qualtrics best-practice engagement library, a custom model, or a hybrid? Who approves final content? | E34: Decides build effort, translation scope and approval path. | F34: Single choice | G34: P1 - Must answer | I34: HR / People Leadership | J34: Week 4 | L34: Not started
A35: ENG-03 | B35: Employee Engagement Survey | C35: ENG | D35: Census or sample? What participation target do you set, and what was achieved last time? | E35: Sets licence volume, reminder strategy and success KPI. | F35: Free text | G35: P2 - Should answer | I35: HR / People Leadership | J35: Week 4 | L35: Not started
A36: ENG-04 | B36: Employee Engagement Survey | C36: ENG | D36: Which results cuts are required (org unit, location, job level, tenure, age band, gender, manager)? What is the minimum group size for reporting? | E36: Drives data attributes needed from EC and the anonymity threshold. | F36: List / table | G36: P1 - Must answer | H36: ★ | I36: People Analytics | J36: Week 4 | L36: Not started
A37: ENG-05 | B37: Employee Engagement Survey | C37: ENG | D37: Will the survey be anonymous or confidential? Will SF attributes be attached to responses, and how will employees be told? | E37: The promise made to employees must match the technical design. | F37: Single choice | G37: P1 - Must answer | H37: ★ | I37: Legal / DPO / Employee Relations | J37: Week 4 | L37: Not started
A38: ENG-06 | B38: Employee Engagement Survey | C38: ENG | D38: Is benchmarking required (internal, industry, external)? Against which peer groups? | E38: Determines licensed benchmark content and comparisons. | F38: Free text | G38: P2 - Should answer | I38: People Analytics | J38: Week 8 | L38: Not started
A39: ENG-07 | B39: Employee Engagement Survey | C39: ENG | D39: Who sees results (executives, HRBPs, all people managers), and when? What is the cascade process? | E39: Defines roles, dashboard design and release gates. | F39: List / table | G39: P1 - Must answer | I39: HR / People Leadership | J39: Week 8 | L39: Not started
A40: ENG-08 | B40: Employee Engagement Survey | C40: ENG | D40: How will open-text comments be handled: languages, redaction of names, and escalation of sensitive content (harassment, safety)? | E40: Duty-of-care and anonymity obligations. | F40: Free text | G40: P1 - Must answer | H40: ★ | I40: Legal / DPO / Employee Relations | J40: Week 8 | L40: Not started
A41: ENG-09 | B41: Employee Engagement Survey | C41: ENG, MGR | D41: What are managers expected to do with results (action plans, deadlines, tracking)? Should plans link to SF goals or development plans? | E41: Closing the loop is what makes engagement credible. | F41: Free text | G41: P1 - Must answer | H41: ★ | I41: HR / People Leadership | J41: Week 8 | L41: Not started
...

Sheet SF Module Readiness
A1: SuccessFactors Module Readiness
A2: Status pre-filled from what you told us: Employee Central and PMGM are live. Confirm everything else.
A4: SuccessFactors module | B4: Status (confirm) | C4: EX relevance | D4: Qualtrics touchpoint | E4: Data / trigger needed | F4: Question to confirm | G4: Planned go-live date | H4: In scope for EX? | I4: Notes
A5: Employee Central (core HR) | B5: Live | C5: Primary data source for every EX use case | D5: Employee directory, hierarchy, lifecycle triggers | E5: Person, employment, job, organisation, manager, events | F5: Which EC changes are planned before go-live?
A6: Performance & Goals (PMGM) | B6: Live | C6: 360 overlap; post-review pulse; link to ratings | D6: 360 decision, review-cycle calendar, optional rating joins | E6: Cycle dates, form templates, multi-rater use, ratings | F6: Does PMGM already run multi-rater feedback, and which tool will own 360?
A7: Continuous Performance Management | B7: To confirm | C7: Check-in and feedback pulses | D7: Manager conversation pulses | E7: Activity events | F7: Is CPM in use or planned?
A8: Recruiting Management | B8: Planned - confirm date | C8: Candidate experience | D8: Stage-triggered candidate surveys | E8: Requisition, application stage, applicant contact | F8: Go-live date and applicant-privacy constraints?
A9: Recruiting Marketing / CRM | B9: To confirm | C9: Employer brand and candidate funnel | D9: Candidate pulse (optional) | E9: Career site events | F9: In scope?
A10: Onboarding | B10: Planned - confirm date | C10: Onboarding experience | D10: Day-1 / 30 / 90 surveys, task-based triggers | E10: Hire event, tasks, buddy, manager | F10: Go-live date; is a manual trigger acceptable at launch?
A11: Offboarding (EC) | B11: To confirm | C11: Exit experience | D11: Pre-exit and exit surveys | E11: Termination event, last day, reason code | F11: Is offboarding configured and reliable?
A12: Learning | B12: Planned - confirm date | C12: Learning experience; manager development follow-up | D12: Course-completion pulse; link from action plans | E12: Course completions | F12: Go-live date; integration expectations?
A13: Succession & Development | B13: Planned - confirm date | C13: 360 results into development plans | D13: Development plan linkage | E13: Talent profile, development goals | F13: Should 360 results flow here or stay confidential?
A14: Compensation | B14: Planned - confirm date | C14: Pay perception (survey content only) | D14: None required | E14: None | F14: Any rule against linking pay data to survey data?
A15: Employee Central Payroll | B15: To confirm | C15: Pay-cycle blackout dates | D15: Calendar only | E15: Payroll calendar | F15: Avoid surveys in payroll-close windows?
A16: Time Management / Time Tracking | B16: To confirm | C16: Work-pattern segmentation (optional) | D16: Optional attributes | E16: Work schedule | F16: Needed for segmentation?
... A20: SF Intelligent Services / Integration Center | B20: To confirm | C20: Event-driven triggers | D20: Lifecycle event feed | E20: Hire, transfer and termination events | F20: Are these enabled and who maintains them?

Sheet Data Inventory
A1: Employee Central Data Inventory
A2: List typical EC data areas are indicative; confirm actual field names and permission rules with your HRIS lead.
A4: Attribute | B4: EC area (typical) | C4: Purpose in Qualtrics | D4: Sensitivity | E4: Needed for | F4: Available in EC? | G4: Data quality (1-5) | H4: Approved to share? | I4: Source field / notes
A5: Person ID / User ID | B5: Person information | C5: Key / identifier | D5: Medium | E5: All
A6: First and last name | B6: Personal information | C6: Contact / display | D6: Medium | E6: All
A7: Business email | B7: Email information | C7: Contact | D7: Medium | E7: All
A8: Personal email | B8: Email information | C8: Contact (leavers, deskless) | D8: High | E8: Exit, Onboarding, Candidate
A9: Mobile number | B9: Phone information | C9: Contact (SMS) | D9: High | E9: Pulse, Deskless
A10: Preferred language | B10: Personal information | C10: Survey language | D10: Low | E10: All
A11: Hire date / original start date | B11: Employment information | C11: Lifecycle trigger | D11: Low | E11: Onboarding, Engagement tenure
A12: Termination date | B12: Employment information | C12: Lifecycle trigger | D12: Medium | E12: Exit
A13: Event / event reason | B13: Job information | C13: Trigger and eligibility filter | D13: Low | E13: Onboarding, Exit, Moves
A14: Employment status | B14: Job information | C14: Eligibility | D14: Low | E14: All
A15: Employee class / worker type | B15: Job information | C15: Eligibility and segmentation | D15: Low | E15: All
A16: Full-time / part-time, FTE | B16: Job information | C16: Segmentation | D16: Low | E16: Engagement
... A34: Leave start / return date | B34: Time off or employment | C34: Return-from-leave trigger | D34: Medium | E34: Moves
A36: Do not send government ID numbers, bank details or other regulated identifiers in this workbook. Sensitive attributes are listed only to decide whether they are permitted.

Sheet Timeline & Risks
A1: 16-Week Plan and Risk Register
A2: Illustrative plan for a go-live in weeks 14-15 (Feb 2027). Change the start date in the blue cell; week headers update.
A4: Project start (Monday) | B4: 46328
A6: Phase | B6: Key activities | C6: =$B$4+7*0 -> 46328 | D6: =$B$4+7*1 -> 46335 | E6: =$B$4+7*2 -> 46342 | F6: =$B$4+7*3 -> 46349 | G6: =$B$4+7*4 -> 46356 | H6: =$B$4+7*5 -> 46363 | I6: =$B$4+7*6 -> 46370 | J6: =$B$4+7*7 -> 46377 | K6: =$B$4+7*8 -> 46384 | L6: =$B$4+7*9 -> 46391 | M6: =$B$4+7*10 -> 46398 | N6: =$B$4+7*11 -> 46405 | O6: =$B$4+7*12 -> 46412 | P6: =$B$4+7*13 -> 46419 | Q6: =$B$4+7*14 -> 46426 | R6: =$B$4+7*15 -> 46433
A7: Mobilise & discover | B7: Kick-off, questionnaire issued and walked through, stakeholder interviews, licence and tenant confirmed, security and legal review started
A8: Design | B8: Use-case scope confirmed, hierarchy and data mapping, integration design, roles and anonymity rules, survey content and translations started
A9: Build & integrate | B9: Directory and integration build, project configuration, dashboards, roles, messages, translations loaded
A10: Test & pilot | B10: Integration test, UAT, privacy and accessibility checks, pilot with a small population
A11: Go-live preparation | B11: Communications, manager toolkit, training, support model, cutover plan
A12: Go-live | B12: Launch Wave 1 use cases; monitor syncs and participation
A13: Hypercare & handover | B13: Daily monitoring, fixes, knowledge transfer, Wave 2 planning
A15: Plan notes
A16: Year-end holidays typically remove one to two weeks of capacity between late December and early January. Check regional calendars and festival dates for each country.
A17: Security, privacy and consultation work starts in week 1 because it often gates access to real employee data.
A18: If Wave 1 is limited to Engagement or Pulse plus Onboarding and Exit, the plan holds. Adding 360 or candidate experience usually needs Phase 2.
A20: Risk register
A21: Risk | B21: Mitigation | C21: Likelihood (1-5) | D21: Impact (1-5) | E21: Score | F21: Rating | G21: Owner
A22: Vendor security, privacy or DPIA review runs past the build start | B22: Start reviews in week 1; share Qualtrics security pack early; build on test data in the meantime | C22: 4 | D22: 5 | E22: =C22*D22 -> 20 | F22: =IF(E22>=15,"High",IF(E22>=8,"Medium","Low")) -> High | G22: Security & Privacy
A23: Works council or union consultation required in one or more countries | B23: Identify countries in week 2; launch in unaffected countries first; prepare consultation pack | C23: 3 | D23: 5 | E23: =C23*D23 -> 15 | F23: =IF(E23>=15,"High",IF(E23>=8,"Medium","Low")) -> High | G23: Legal / Employee Relations
A24: Other SF modules go live in the same window and consume the same people | B24: Agree a single resource plan and change calendar; avoid EX testing during cutovers | C24: 4 | D24: 4 | E24: =C24*D24 -> 16 | F24: =IF(E24>=15,"High",IF(E24>=8,"Medium","Low")) -> High | G24: PMO
A25: EC data quality (manager, email, location) creates wrong survey populations | B25: Run a data-quality profile in weeks 2-3; fix at source; add exception reports | C25: 4 | D25: 4 | E25: =C25*D25 -> 16 | F25: =IF(E25>=15,"High",IF(E25>=8,"Medium","Low")) -> High | G25: HRIS
A26: Integration capacity (BTP or API skills) is not available | B26: Confirm the build owner in week 2; fall back to SFTP file feed for Wave 1 | C26: 3 | D26: 4 | E26: =C26*D26 -> 12 | F26: =IF(E26>=15,"High",IF(E26>=8,"Medium","Low")) -> Medium | G26: IT
A27: Lifecycle triggers depend on modules that are not yet live | B27: Use EC hire and termination events; manual or file triggers for the rest; defer candidate use case | C27: 4 | D27: 3 | E27: =C27*D27 -> 12 | F27: =IF(E27>=15,"High",IF(E27>=8,"Medium","Low")) -> Medium | G27: HRIS
A28: Translation and legal text approval delays survey content | B28: Freeze source content by week 5; start translation by week 6; limit launch languages | C28: 3 | D28: 4 | E28: =C28*D28 -> 12 | F28: =IF(E28>=15,"High",IF(E28>=8,"Medium","Low")) -> Medium | G28: HR
A29: Anonymity thresholds not met for small teams | B29: Agree minimum group size and roll-up rules in design; test with real hierarchy | C29: 4 | D29: 3 | E29: =C29*D29 -> 12 | F29: =IF(E29>=15,"High",IF(E29>=8,"Medium","Low")) -> Medium | G29: People Analytics
A30: Holiday and year-end periods remove key people for one to two weeks | B30: Plan around regional calendars; book UAT and pilot slots early | C30: 4 | D30: 3 | E30: =C30*D30 -> 12 | F30: =IF(E30>=15,"High",IF(E30>=8,"Medium","Low")) -> Medium | G30: PMO
A31: 360 overlaps with PMGM multi-rater and creates two processes | B31: Decide the system of record in week 2; start with one population | C31: 3 | D31: 3 | E31: =C31*D31 -> 9 | F31: =IF(E31>=15,"High",IF(E31>=8,"Medium","Low")) -> Medium | G31: Talent & L&D
A32: Employee trust is low and participation falls short | B32: Early comms, clear anonymity message, visible leader sponsorship, you-said-we-did plan | C32: 3 | D32: 4 | E32: =C32*D32 -> 12 | F32: =IF(E32>=15,"High",IF(E32>=8,"Medium","Low")) -> Medium | G32: Internal Communications
A33: Invitation emails blocked or filtered | B33: Allow-list sender and domain; test deliverability in UAT; use multiple channels | C33: 3 | D33: 3 | E33: =C33*D33 -> 9 | F33: =IF(E33>=15,"High",IF(E33>=8,"Medium","Low")) -> Medium | G33: IT
... A35: AI features not approved by Legal or employee representatives | B35: Raise in week 2; go live without AI summaries if needed | C35: 2 | D35: 3 | E35: =C35*D35 -> 6 | F35: =IF(E35>=15,"High",IF(E35>=8,"Medium","Low")) -> Low | G35: Legal
A37: Likelihood and impact scores are our starting estimates (blue). Replace them with the client's view.

Sheet Stakeholders
A1: Stakeholders and Respondents
A2: Name the person for each role so questions can be routed. Add rows as needed.
A4: Role | B4: Why needed | C4: Typical involvement | D4: Name | E4: Email | F4: Availability / notes
A5: Executive Sponsor | B5: Owns scope, budget and date decisions | C5: Weeks 1-16
A6: CHRO / Head of People | B6: Business owner of EX outcomes | C6: Weeks 1-16
A7: HRIS / SuccessFactors Lead | B7: EC data, triggers, module calendar | C7: Weeks 1-16
A8: People Analytics Lead | B8: Hierarchy, anonymity, reporting design | C8: Weeks 2-16
A9: Talent & L&D Lead | B9: 360, manager development, competencies | C9: Weeks 2-14
A10: Talent Acquisition Lead | B10: Onboarding and candidate experience | C10: Weeks 2-12
A11: IT / Integration Architect | B11: Integration, SSO, environments | C11: Weeks 1-16
A12: Information Security Lead | B12: Vendor review, access, API security | C12: Weeks 1-12
A13: Data Protection Officer / Legal | B13: DPIA, consent, retention, AI policy | C13: Weeks 1-12
A14: Employee Relations / Works Council liaison | B14: Consultation and country rules | C14: Weeks 1-10
A15: Internal Communications Lead | B15: Invitations, trust messaging, FAQ | C15: Weeks 4-16
A16: Procurement / Finance | B16: Contract, licences, budget | C16: Weeks 1-6
... A20: Pilot Managers | B20: Pilot, feedback on toolkit | C20: Weeks 10-14

Sheet Sources
A1: Sources
A3: Source | B3: Link
A4: Qualtrics Support: Step 1, Getting Ready to Launch Your 360 Project | B4: https://www.qualtrics.com/support/employee-experience/getting-started-employee-experience/360-onboarding/form-building/
A5: Qualtrics and SAP announce new partnership (SAP Endorsed Apps), Jan 2025 | B5: https://www.qualtrics.com/articles/news/qualtrics-and-sap-announce-new-partnership-to-help-organizations-deliver-great-employee-experiences/
A6: SAP Store: Qualtrics XM for Employee Experience | B6: https://www.sap.com/uk/products/hcm/partners/qualtrics-llc-qualtrics-employee-experience.html
A7: SAP User Groups: Qualtrics / SuccessFactors integration roadmap (archived deck) | B7: https://assets.dm.ux.sap.com/webinars/sap-user-groups-k4u/pdfs/191212_qualtrics_successfactors_roadmap.pdf
A8: TechTarget: What capabilities does Qualtrics EmployeeXM offer? | B8: https://www.techtarget.com/enterprise-software/answer/What-capabilities-does-Qualtrics-EmployeeXM-offer
A10: Our own recommendations (use-case fit, plan, risks) are judgement, not vendor statements.
